Workbook

Sheet README
A1: MPEF Meeting Scorecard — auto-calculating workbook
A2: Meeting Performance Evaluation Framework v1.0 · every score is a formula; nothing is typed in by hand except evidence.
B4: HOW TO USE
B5: 1. Extract | C5: Run your AI extraction over the meeting artifacts (transcript, recording, minutes, chat, attendance) — or count manually.
B6: 2. Fill yellow cells | C6: Enter the extracted values in the YELLOW cells on: Meeting, Agenda, Participants, Presenters, Interaction, Outcomes.
B7: 3. Read Scorecard | C7: The Scorecard sheet computes every metric, all six dimension scores, the MPI and its band — live.
B8: 4. Calibrate (optional) | C8: Adjust weights and normalization bands on Config. Freeze them afterwards so meetings stay comparable.
B10: COLOR LEGEND
B11: Yellow fill, blue text | C11: Input cell — enter your extracted evidence here. The workbook ships with one full realistic example meeting.
B12: Black text | C12: Calculated — do not overtype. Formulas recalculate automatically.
B13: Green text | C13: Pulled from another sheet.
B15: METHOD NOTES (Excel adaptations of the framework, documented for auditability)
B16: Speaking balance | C16: 1 − Gini coefficient, computed with the rank formula G = 2·Σ(rank·talk)/(n·Σtalk) − (n+1)/n over attendees. Ties share the lower rank (close approximation).
B17: Sequence adherence | C17: Share of agenda items discussed in their planned position (position-match proxy for the framework's LCS measure).
B18: Speaking pace | C18: Average words-per-minute deviation from the 130–170 band, per presenter (proxy for per-minute in-band share).
B19: Times | C19: Start/end times assume the meeting does not cross midnight.
B20: Not assessable | C20: Leave an input blank and its metric drops out; each dimension re-averages over what remains, and the MPI re-weights over assessable dimensions — nothing is ever estimated.
B21: Source | C21: All defaults (weights, bands, thresholds) come from the MPEF v1.0 framework document, §2–§3. Values in the example meeting are illustrative, supplied with this workbook.

Sheet Scorecard
A1: Scorecard — dimensions, MPI and band
A2: All values below are live formulas. Green = pulled from other sheets; bands and weights come from Config.
A4: Meeting | B4: =Meeting!B5 -> Weekly Product Review | D4: MPI
A5: Date | B5: =Meeting!B6 -> 2026-08-12 | D5: =IF(C49="","",ROUND(C49,0)) -> 77 | E5: =IF(C50="","",C50) -> Productive
D6: 0–100, weighted over assessable dimensions
A9: Metric detail
A10: Dim | B10: Metric | C10: Raw value | D10: Score 0–100
A11: D1 | B11: Coverage rate | C11: =Agenda!B21 -> 0.83333333 | D11: =IF(C11="","",MAX(0,MIN(100,C11*100))) -> 83.333333
A12: D1 | B12: Avg time adherence | C12: =Agenda!B22 -> 0.58333333 | D12: =IF(C12="","",MAX(0,MIN(100,C12*100))) -> 58.333333
A13: D1 | B13: Sequence adherence | C13: =Agenda!B23 -> 0.5 | D13: =IF(C13="","",MAX(0,MIN(100,C13*100))) -> 50
A14: D1 | B14: Off-agenda ratio | C14: =Meeting!B24 -> 0.11538462 | D14: =IF(C14="","",MAX(0,MIN(100,100*(C14-Config!$E$11)/(Config!$F$11-Config!$E$11)))) -> 81.318681
A15: D2 | B15: Start delay (min) | C15: =Meeting!B21 -> 4 | D15: =IF(C15="","",MAX(0,MIN(100,100*(C15-Config!$E$7)/(Config!$F$7-Config!$E$7)))) -> 73.333333
A16: D2 | B16: Duration overrun | C16: =Meeting!B22 -> 0.05 | D16: =IF(C16="","",MAX(0,MIN(100,100*(C16-Config!$E$8)/(Config!$F$8-Config!$E$8)))) -> 90
A17: D2 | B17: Dead time ratio | C17: =Meeting!B23 -> 0.063492063 | D17: =IF(C17="","",MAX(0,MIN(100,100*(C17-Config!$E$9)/(Config!$F$9-Config!$E$9)))) -> 78.835979
A18: D2 | B18: Decision latency (min) | C18: =Meeting!B13 -> 12 | D18: =IF(C18="","",MAX(0,MIN(100,100*(C18-Config!$E$10)/(Config!$F$10-Config!$E$10)))) -> 72
A19: D3 | B19: Allocation adherence | C19: =Presenters!B13 -> 0.95 | D19: =IF(C19="","",MAX(0,MIN(100,C19*100))) -> 95
A20: D3 | B20: Pace deviation (WPM) | C20: =Presenters!B14 -> 10 | D20: =IF(C20="","",MAX(0,MIN(100,100*(C20-Config!$E$12)/(Config!$F$12-Config!$E$12)))) -> 75
A21: D3 | B21: Filler per 100 words | C21: =Presenters!B15 -> 2.4210526 | D21: =IF(C21="","",MAX(0,MIN(100,100*(C21-Config!$E$13)/(Config!$F$13-Config!$E$13)))) -> 79.699248
A22: D3 | B22: Q&A responsiveness | C22: =Presenters!B16 -> 0.875 | D22: =IF(C22="","",MAX(0,MIN(100,C22*100))) -> 87.5
A23: D3 | B23: Response latency (s) | C23: =Presenters!B17 -> 11.5 | D23: =IF(C23="","",MAX(0,MIN(100,100*(C23-Config!$E$14)/(Config!$F$14-Config!$E$14)))) -> 88.181818
A24: D3 | B24: Monologue ratio | C24: =Presenters!B18 -> 0.47777778 | D24: =IF(C24="","",MAX(0,MIN(100,100*(C24-Config!$E$15)/(Config!$F$15-Config!$E$15)))) -> 64.444444
A25: D4 | B25: Attendance rate | C25: =Participants!B23 -> 0.8 | D25: =IF(C25="","",MAX(0,MIN(100,C25*100))) -> 80
A26: D4 | B26: Avg retention | C26: =Participants!B24 -> 0.93849206 | D26: =IF(C26="","",MAX(0,MIN(100,C26*100))) -> 93.849206
A27: D4 | B27: Active contributor ratio | C27: =Participants!B25 -> 0.875 | D27: =IF(C27="","",MAX(0,MIN(100,C27*100))) -> 87.5
A28: D4 | B28: Speaking balance (1−Gini) | C28: =Participants!B27 -> 0.61538462 | D28: =IF(C28="","",MAX(0,MIN(100,C28*100))) -> 61.538462
A29: D4 | B29: Interaction density (turns/10m) | C29: =Interaction!B14 -> 8 | D29: =IF(C29="","",MAX(0,MIN(100,100*(C29-Config!$E$16)/(Config!$F$16-Config!$E$16)))) -> 60
A30: D5 | B30: Question resolution rate | C30: =Interaction!B9 -> 0.83333333 | D30: =IF(C30="","",MAX(0,MIN(100,C30*100))) -> 83.333333
A31: D5 | B31: Feedback instances | C31: =Interaction!B10 -> 6 | D31: =IF(C31="","",MAX(0,MIN(100,100*(C31-Config!$E$17)/(Config!$F$17-Config!$E$17)))) -> 75
A32: D5 | B32: Chat per attendee | C32: =Interaction!B12 -> 0.625 | D32: =IF(C32="","",MAX(0,MIN(100,100*(C32-Config!$E$18)/(Config!$F$18-Config!$E$18)))) -> 62.5
A33: D5 | B33: Interruptions per 10 min | C33: =Interaction!B13 -> 1.5 | D33: =IF(C33="","",MAX(0,MIN(100,100*(C33-Config!$E$19)/(Config!$F$19-Config!$E$19)))) -> 81.818182
A34: D6 | B34: Decision yield | C34: =Agenda!B26 -> 1 | D34: =IF(C34="","",MAX(0,MIN(100,C34*100))) -> 100
A35: D6 | B35: Action completeness | C35: =Outcomes!B7 -> 0.71428571 | D35: =IF(C35="","",MAX(0,MIN(100,C35*100))) -> 71.428571
A36: D6 | B36: Topic resolution (1−unresolved) | C36: =Agenda!B27 -> 0.2 | D36: =IF(C36="","",MAX(0,MIN(100,(1-C36)*100))) -> 80
A37: D6 | B37: MoM fidelity | C37: =Outcomes!B15 -> 0.82638889 | D37: =IF(C37="","",MAX(0,MIN(100,C37*100))) -> 82.638889
A38: D7 | B38: Prior-action closure (info only) | C38: =Outcomes!B20 -> 0.66666667 | D38: =IF(C38="","",MAX(0,MIN(100,C38*100))) -> 66.666667
A39: D7 | B39: Topic recurrence, lower better (info) | C39: =Outcomes!B23 -> 0.33333333 | D39: =IF(C39="","",MAX(0,MIN(100,(1-C39)*100))) -> 66.666667
A41: Dimension summary
A42: Dimension | B42: Weight | C42: Score | D42: Assessable | E42: Score (num)
A43: D1 Agenda Discipline | B43: =Config!B6 -> 20 | C43: =IFERROR(AVERAGE(D11:D14),"") -> 68.246337 | D43: =IF(COUNT(D11:D14)>0,1,0) -> 1 | E43: =IF(D43=0,0,C43) -> 68.246337
A44: D2 Time Efficiency | B44: =Config!B7 -> 15 | C44: =IFERROR(AVERAGE(D15:D18),"") -> 78.542328 | D44: =IF(COUNT(D15:D18)>0,1,0) -> 1 | E44: =IF(D44=0,0,C44) -> 78.542328
...

Sheet Config
A1: Configuration
A2: Dimension weights, MPI bands and normalization bands. Blue cells are editable; freeze after calibration.
A4: Dimension weights | D4: Normalization bands
A5: Dimension | B5: Weight | D5: Score = 100·(value − worst)/(best − worst), clamped to 0–100. Direction is encoded by which end is 'best'.
A6: D1 Agenda Discipline | B6: 20 | D6: Metric | E6: Worst (=0) | F6: Best (=100) | G6: Unit / note
A7: D2 Time Efficiency | B7: 15 | D7: Start delay | E7: 15 | F7: 0 | G7: minutes late
A8: D3 Presenter Effectiveness | B8: 20 | D8: Duration overrun | E8: 0.5 | F8: 0 | G8: fraction of scheduled length
A9: D4 Participation | B9: 20 | D9: Dead time ratio | E9: 0.3 | F9: 0 | G9: fraction of meeting
A10: D5 Interaction Quality | B10: 10 | D10: Decision latency | E10: 30 | F10: 5 | G10: minutes from topic open to decision
A11: D6 Outcomes | B11: 15 | D11: Off-agenda ratio | E11: 0.4 | F11: 0.05 | G11: fraction of talk time
A12: Total | B12: =SUM(B6:B11) -> 100 | D12: Pace deviation | E12: 40 | F12: 0 | G12: avg WPM outside 130–170 band
D13: Filler density | E13: 8 | F13: 1 | G13: filler words per 100 words
D14: Response latency | E14: 60 | F14: 5 | G14: seconds, question end to answer start
A15: MPI bands (ascending) | D15: Monologue ratio | E15: 0.8 | F15: 0.3 | G15: longest turn / presenter talk time
A16: Min score | B16: Band | D16: Interaction density | E16: 2 | F16: 12 | G16: speaker turns per 10 min
A17: 0 | B17: Ineffective | D17: Feedback instances | E17: 0 | F17: 8 | G17: count per meeting
A18: 50 | B18: Needs Improvement | D18: Chat engagement | E18: 0 | F18: 1 | G18: substantive messages per attendee
A19: 70 | B19: Productive | D19: Interruption rate | E19: 6 | F19: 0.5 | G19: overlaps > 2 s per 10 min
A20: 85 | B20: Highly Productive

Sheet Meeting
A1: Meeting — metadata & meeting-level evidence
A2: Yellow = enter. Times assume same-day meetings.
A4: Inputs (from artifacts / extraction)
A5: Meeting title | B5: Weekly Product Review | C5: Source: calendar invite
A6: Date | B6: 2026-08-12
A7: Scheduled start | B7: 0.41666667
A8: Scheduled end | B8: 0.45833333
A9: Actual start (first substantive utterance) | B9: 0.41944444 | C9: Source: recording / diarization
A10: Actual end | B10: 0.46319444
A11: Invitees (count) | B11: 10
A12: Dead time — silence >30s + logistics (min) | B12: 4
A13: Avg decision latency (min, topic open → decision) | B13: 12
A14: Off-agenda talk time (min) | B14: 6
A15: Total talk time, all speakers (min) | B15: 52 | C15: Sum of diarized speaker time; denominator for off-agenda ratio
A18: Calculated
A19: Scheduled duration (min) | B19: =(B8-B7)*1440 -> 60
A20: Actual duration (min) | B20: =(B10-B9)*1440 -> 63
A21: Start delay (min) | B21: =MAX(0,(B9-B7)*1440) -> 4
A22: Duration overrun (fraction) | B22: =IFERROR(MAX(0,(B20-B19)/B19),"") -> 0.05
A23: Dead time ratio | B23: =IFERROR(B12/B20,"") -> 0.063492063
A24: Off-agenda ratio | B24: =IFERROR(B14/B15,"") -> 0.11538462

Sheet Agenda
A1: Agenda — coverage, timing, order, closure
A2: One row per planned agenda item. Yellow = enter from agenda + extraction. Y/N fields uppercase.
A4: Item | B4: Owner | C4: Planned min | D4: Planned order | E4: Actual min | F4: Actual order | G4: Substantive? (Y/N) | H4: Decision expected? (Y/N) | I4: Decision made? (Y/N) | J4: Closed w/ decision or action? (Y/N) | K4: Time adherence | L4: Order match
A5: KPI review | B5: Sara | C5: 10 | D5: 1 | E5: 12 | F5: 1 | G5: Y | H5: N | I5: N | J5: Y | K5: =IF($A5="","",IF(C5=0,"",MAX(0,1-ABS(E5-C5)/C5))) -> 0.8 | L5: =IF($A5="","",IF(F5=D5,1,0)) -> 1
A6: Roadmap update | B6: Amir | C6: 10 | D6: 2 | E6: 15 | F6: 2 | G6: Y | H6: Y | I6: Y | J6: Y | K6: =IF($A6="","",IF(C6=0,"",MAX(0,1-ABS(E6-C6)/C6))) -> 0.5 | L6: =IF($A6="","",IF(F6=D6,1,0)) -> 1
A7: Launch go/no-go | B7: Lina | C7: 10 | D7: 3 | E7: 9 | F7: 4 | G7: Y | H7: Y | I7: Y | J7: Y | K7: =IF($A7="","",IF(C7=0,"",MAX(0,1-ABS(E7-C7)/C7))) -> 0.9 | L7: =IF($A7="","",IF(F7=D7,1,0)) -> 0
A8: Budget check | B8: Omar | C8: 10 | D8: 4 | E8: 8 | F8: 3 | G8: Y | H8: N | I8: N | J8: Y | K8: =IF($A8="","",IF(C8=0,"",MAX(0,1-ABS(E8-C8)/C8))) -> 0.8 | L8: =IF($A8="","",IF(F8=D8,1,0)) -> 0
A9: Hiring update | B9: Sara | C9: 10 | D9: 5 | E9: 5 | F9: 5 | G9: Y | H9: N | I9: N | J9: N | K9: =IF($A9="","",IF(C9=0,"",MAX(0,1-ABS(E9-C9)/C9))) -> 0.5 | L9: =IF($A9="","",IF(F9=D9,1,0)) -> 1
A10: AOB | B10: Sara | C10: 10 | D10: 6 | E10: 0 | G10: N | H10: N | I10: N | J10: N | K10: =IF($A10="","",IF(C10=0,"",MAX(0,1-ABS(E10-C10)/C10))) -> 0 | L10: =IF($A10="","",IF(F10=D10,1,0)) -> 0
K11: =IF($A11="","",IF(C11=0,"",MAX(0,1-ABS(E11-C11)/C11))) | L11: =IF($A11="","",IF(F11=D11,1,0))
K12: =IF($A12="","",IF(C12=0,"",MAX(0,1-ABS(E12-C12)/C12))) | L12: =IF($A12="","",IF(F12=D12,1,0))
K13: =IF($A13="","",IF(C13=0,"",MAX(0,1-ABS(E13-C13)/C13))) | L13: =IF($A13="","",IF(F13=D13,1,0))
K14: =IF($A14="","",IF(C14=0,"",MAX(0,1-ABS(E14-C14)/C14))) | L14: =IF($A14="","",IF(F14=D14,1,0))
K15: =IF($A15="","",IF(C15=0,"",MAX(0,1-ABS(E15-C15)/C15))) | L15: =IF($A15="","",IF(F15=D15,1,0))
K16: =IF($A16="","",IF(C16=0,"",MAX(0,1-ABS(E16-C16)/C16))) | L16: =IF($A16="","",IF(F16=D16,1,0))
A18: Aggregates
A19: Items planned | B19: =COUNTIF(A5:A16,"<>") -> 6
A20: Items substantively discussed | B20: =COUNTIFS(A5:A16,"<>",G5:G16,"Y") -> 5
A21: Coverage rate | B21: =IFERROR(B20/B19,"") -> 0.83333333
A22: Avg time adherence | B22: =IFERROR(AVERAGE(K5:K16),"") -> 0.58333333
A23: Sequence adherence | B23: =IFERROR(SUM(L5:L16)/B19,"") -> 0.5
A24: Decisions expected | B24: =COUNTIF(H5:H16,"Y") -> 2
A25: Decisions made (of expected) | B25: =COUNTIFS(H5:H16,"Y",I5:I16,"Y") -> 2
A26: Decision yield | B26: =IF(B24=0,"",B25/B24) -> 1
A27: Unresolved ratio (discussed, not closed) | B27: =IFERROR(COUNTIFS(G5:G16,"Y",J5:J16,"N")/B20,"") -> 0.2

Sheet Participants
A1: Participants — attendance, talk time, contribution mix
A2: One row per invitee. Counts come from utterance classification.
A4: Name / ID | B4: Role | C4: Present? (Y/N) | D4: Minutes present | E4: Talk min | F4: Questions | G4: Answers | H4: Proposals | I4: Risks raised | J4: Info shared | K4: Substantive total | L4: Active (1/0) | M4: Talk share | N4: Rank (helper)
A5: Sara | B5: Organizer | C5: Y | D5: 63 | E5: 14 | F5: 2 | G5: 3 | H5: 1 | I5: 0 | J5: 2 | K5: =IF($A5="","",SUM(F5:J5)) -> 8 | L5: =IF($A5="","",IF(K5>0,1,0)) -> 1 | M5: =IF($A5="","",IFERROR(E5/SUMIF($C$5:$C$19,"Y",$E$5:$E$19),"")) -> 0.26923077 | N5: =IF(OR($A5="",$C5<>"Y"),"",COUNTIFS($C$5:$C$19,"Y",$E$5:$E$19,"<"&E5)+1) -> 8
A6: Amir | B6: Presenter | C6: Y | D6: 63 | E6: 12 | F6: 1 | G6: 4 | H6: 1 | I6: 0 | J6: 3 | K6: =IF($A6="","",SUM(F6:J6)) -> 9 | L6: =IF($A6="","",IF(K6>0,1,0)) -> 1 | M6: =IF($A6="","",IFERROR(E6/SUMIF($C$5:$C$19,"Y",$E$5:$E$19),"")) -> 0.23076923 | N6: =IF(OR($A6="",$C6<>"Y"),"",COUNTIFS($C$5:$C$19,"Y",$E$5:$E$19,"<"&E6)+1) -> 7
A7: Lina | B7: Presenter | C7: Y | D7: 63 | E7: 9 | F7: 1 | G7: 3 | H7: 1 | I7: 1 | J7: 1 | K7: =IF($A7="","",SUM(F7:J7)) -> 7 | L7: =IF($A7="","",IF(K7>0,1,0)) -> 1 | M7: =IF($A7="","",IFERROR(E7/SUMIF($C$5:$C$19,"Y",$E$5:$E$19),"")) -> 0.17307692 | N7: =IF(OR($A7="",$C7<>"Y"),"",COUNTIFS($C$5:$C$19,"Y",$E$5:$E$19,"<"&E7)+1) -> 6
A8: Omar | B8: Participant | C8: Y | D8: 63 | E8: 6 | F8: 3 | G8: 0 | H8: 0 | I8: 1 | J8: 1 | K8: =IF($A8="","",SUM(F8:J8)) -> 5 | L8: =IF($A8="","",IF(K8>0,1,0)) -> 1 | M8: =IF($A8="","",IFERROR(E8/SUMIF($C$5:$C$19,"Y",$E$5:$E$19),"")) -> 0.11538462 | N8: =IF(OR($A8="",$C8<>"Y"),"",COUNTIFS($C$5:$C$19,"Y",$E$5:$E$19,"<"&E8)+1) -> 5
A9: Dana | B9: Participant | C9: Y | D9: 63 | E9: 5 | F9: 2 | G9: 0 | H9: 1 | I9: 1 | J9: 0 | K9: =IF($A9="","",SUM(F9:J9)) -> 4 | L9: =IF($A9="","",IF(K9>0,1,0)) -> 1 | M9: =IF($A9="","",IFERROR(E9/SUMIF($C$5:$C$19,"Y",$E$5:$E$19),"")) -> 0.096153846 | N9: =IF(OR($A9="",$C9<>"Y"),"",COUNTIFS($C$5:$C$19,"Y",$E$5:$E$19,"<"&E9)+1) -> 4
A10: Karl | B10: Participant | C10: Y | D10: 63 | E10: 3 | F10: 2 | G10: 0 | H10: 0 | I10: 0 | J10: 1 | K10: =IF($A10="","",SUM(F10:J10)) -> 3 | L10: =IF($A10="","",IF(K10>0,1,0)) -> 1 | M10: =IF($A10="","",IFERROR(E10/SUMIF($C$5:$C$19,"Y",$E$5:$E$19),"")) -> 0.057692308 | N10: =IF(OR($A10="",$C10<>"Y"),"",COUNTIFS($C$5:$C$19,"Y",$E$5:$E$19,"<"&E10)+1) -> 3
A11: Mei | B11: Participant | C11: Y | D11: 55 | E11: 2 | F11: 1 | G11: 0 | H11: 0 | I11: 0 | J11: 0 | K11: =IF($A11="","",SUM(F11:J11)) -> 1 | L11: =IF($A11="","",IF(K11>0,1,0)) -> 1 | M11: =IF($A11="","",IFERROR(E11/SUMIF($C$5:$C$19,"Y",$E$5:$E$19),"")) -> 0.038461538 | N11: =IF(OR($A11="",$C11<>"Y"),"",COUNTIFS($C$5:$C$19,"Y",$E$5:$E$19,"<"&E11)+1) -> 2
A12: Tomás | B12: Participant | C12: Y | D12: 40 | E12: 1 | F12: 0 | G12: 0 | H12: 0 | I12: 0 | J12: 0 | K12: =IF($A12="","",SUM(F12:J12)) -> 0 | L12: =IF($A12="","",IF(K12>0,1,0)) -> 0 | M12: =IF($A12="","",IFERROR(E12/SUMIF($C$5:$C$19,"Y",$E$5:$E$19),"")) -> 0.019230769 | N12: =IF(OR($A12="",$C12<>"Y"),"",COUNTIFS($C$5:$C$19,"Y",$E$5:$E$19,"<"&E12)+1) -> 1
K13: =IF($A13="","",SUM(F13:J13)) | L13: =IF($A13="","",IF(K13>0,1,0)) | M13: =IF($A13="","",IFERROR(E13/SUMIF($C$5:$C$19,"Y",$E$5:$E$19),"")) | N13: =IF(OR($A13="",$C13<>"Y"),"",COUNTIFS($C$5:$C$19,"Y",$E$5:$E$19,"<"&E13)+1)
K14: =IF($A14="","",SUM(F14:J14)) | L14: =IF($A14="","",IF(K14>0,1,0)) | M14: =IF($A14="","",IFERROR(E14/SUMIF($C$5:$C$19,"Y",$E$5:$E$19),"")) | N14: =IF(OR($A14="",$C14<>"Y"),"",COUNTIFS($C$5:$C$19,"Y",$E$5:$E$19,"<"&E14)+1)
K15: =IF($A15="","",SUM(F15:J15)) | L15: =IF($A15="","",IF(K15>0,1,0)) | M15: =IF($A15="","",IFERROR(E15/SUMIF($C$5:$C$19,"Y",$E$5:$E$19),"")) | N15: =IF(OR($A15="",$C15<>"Y"),"",COUNTIFS($C$5:$C$19,"Y",$E$5:$E$19,"<"&E15)+1)
K16: =IF($A16="","",SUM(F16:J16)) | L16: =IF($A16="","",IF(K16>0,1,0)) | M16: =IF($A16="","",IFERROR(E16/SUMIF($C$5:$C$19,"Y",$E$5:$E$19),"")) | N16: =IF(OR($A16="",$C16<>"Y"),"",COUNTIFS($C$5:$C$19,"Y",$E$5:$E$19,"<"&E16)+1)
K17: =IF($A17="","",SUM(F17:J17)) | L17: =IF($A17="","",IF(K17>0,1,0)) | M17: =IF($A17="","",IFERROR(E17/SUMIF($C$5:$C$19,"Y",$E$5:$E$19),"")) | N17: =IF(OR($A17="",$C17<>"Y"),"",COUNTIFS($C$5:$C$19,"Y",$E$5:$E$19,"<"&E17)+1)
K18: =IF($A18="","",SUM(F18:J18)) | L18: =IF($A18="","",IF(K18>0,1,0)) | M18: =IF($A18="","",IFERROR(E18/SUMIF($C$5:$C$19,"Y",$E$5:$E$19),"")) | N18: =IF(OR($A18="",$C18<>"Y"),"",COUNTIFS($C$5:$C$19,"Y",$E$5:$E$19,"<"&E18)+1)
K19: =IF($A19="","",SUM(F19:J19)) | L19: =IF($A19="","",IF(K19>0,1,0)) | M19: =IF($A19="","",IFERROR(E19/SUMIF($C$5:$C$19,"Y",$E$5:$E$19),"")) | N19: =IF(OR($A19="",$C19<>"Y"),"",COUNTIFS($C$5:$C$19,"Y",$E$5:$E$19,"<"&E19)+1)
A21: Aggregates
A22: Attendees | B22: =COUNTIF(C5:C19,"Y") -> 8
A23: Attendance rate (vs invitees) | B23: =IFERROR(B22/Meeting!$B$11,"") -> 0.8 | C23: Invitees pulled from Meeting sheet
A24: Avg retention (time present / duration) | B24: =IFERROR(AVERAGEIF(C5:C19,"Y",D5:D19)/Meeting!$B$20,"") -> 0.93849206
A25: Active contributor ratio | B25: =IFERROR(SUM(L5:L19)/B22,"") -> 0.875
A26: Gini coefficient (talk time) | B26: =IFERROR((2*SUMPRODUCT(($C$5:$C$19="Y")*N($N$5:$N$19)*$E$5:$E$19))/(B22*SUMIF(C5:C19,"Y",E5:E19))-(B22+1)/B22,"") -> 0.38461538
A27: Speaking balance (1 − Gini) | B27: =IFERROR(MAX(0,MIN(1,1-B26)),"") -> 0.61538462

Sheet Presenters
A1: Presenters — delivery evidence per presenter
A2: One row per presenter; calculated columns and averages feed dimension D3.
A4: Presenter | B4: Planned min | C4: Actual min | D4: Words spoken | E4: Filler words | F4: Qs received | G4: Qs answered | H4: Median resp latency (s) | I4: Longest turn (min) | J4: Allocation adherence | K4: WPM | L4: Pace deviation | M4: Filler /100w | N4: Q&A rate | O4: Monologue ratio
A5: Amir | B5: 15 | C5: 15 | D5: 2250 | E5: 30 | F5: 5 | G5: 5 | H5: 8 | I5: 6 | J5: =IF($A5="","",IF(B5=0,"",MAX(0,1-ABS(C5-B5)/B5))) -> 1 | K5: =IF($A5="","",IFERROR(D5/C5,"")) -> 150 | L5: =IF($A5="","",IFERROR(MAX(0,130-K5,K5-170),"")) -> 0 | M5: =IF($A5="","",IFERROR(E5/D5*100,"")) -> 1.3333333 | N5: =IF($A5="","",IF(F5=0,"",G5/F5)) -> 1 | O5: =IF($A5="","",IFERROR(I5/C5,"")) -> 0.4
A6: Lina | B6: 10 | C6: 9 | D6: 1710 | E6: 60 | F6: 4 | G6: 3 | H6: 15 | I6: 5 | J6: =IF($A6="","",IF(B6=0,"",MAX(0,1-ABS(C6-B6)/B6))) -> 0.9 | K6: =IF($A6="","",IFERROR(D6/C6,"")) -> 190 | L6: =IF($A6="","",IFERROR(MAX(0,130-K6,K6-170),"")) -> 20 | M6: =IF($A6="","",IFERROR(E6/D6*100,"")) -> 3.5087719 | N6: =IF($A6="","",IF(F6=0,"",G6/F6)) -> 0.75 | O6: =IF($A6="","",IFERROR(I6/C6,"")) -> 0.55555556
J7: =IF($A7="","",IF(B7=0,"",MAX(0,1-ABS(C7-B7)/B7))) | K7: =IF($A7="","",IFERROR(D7/C7,"")) | L7: =IF($A7="","",IFERROR(MAX(0,130-K7,K7-170),"")) | M7: =IF($A7="","",IFERROR(E7/D7*100,"")) | N7: =IF($A7="","",IF(F7=0,"",G7/F7)) | O7: =IF($A7="","",IFERROR(I7/C7,""))
J8: =IF($A8="","",IF(B8=0,"",MAX(0,1-ABS(C8-B8)/B8))) | K8: =IF($A8="","",IFERROR(D8/C8,"")) | L8: =IF($A8="","",IFERROR(MAX(0,130-K8,K8-170),"")) | M8: =IF($A8="","",IFERROR(E8/D8*100,"")) | N8: =IF($A8="","",IF(F8=0,"",G8/F8)) | O8: =IF($A8="","",IFERROR(I8/C8,""))
J9: =IF($A9="","",IF(B9=0,"",MAX(0,1-ABS(C9-B9)/B9))) | K9: =IF($A9="","",IFERROR(D9/C9,"")) | L9: =IF($A9="","",IFERROR(MAX(0,130-K9,K9-170),"")) | M9: =IF($A9="","",IFERROR(E9/D9*100,"")) | N9: =IF($A9="","",IF(F9=0,"",G9/F9)) | O9: =IF($A9="","",IFERROR(I9/C9,""))
J10: =IF($A10="","",IF(B10=0,"",MAX(0,1-ABS(C10-B10)/B10))) | K10: =IF($A10="","",IFERROR(D10/C10,"")) | L10: =IF($A10="","",IFERROR(MAX(0,130-K10,K10-170),"")) | M10: =IF($A10="","",IFERROR(E10/D10*100,"")) | N10: =IF($A10="","",IF(F10=0,"",G10/F10)) | O10: =IF($A10="","",IFERROR(I10/C10,""))
A12: Averages (feed D3)
A13: Avg allocation adherence | B13: =IFERROR(AVERAGE(J5:J10),"") -> 0.95
A14: Avg pace deviation (WPM) | B14: =IFERROR(AVERAGE(L5:L10),"") -> 10
A15: Avg filler per 100 words | B15: =IFERROR(AVERAGE(M5:M10),"") -> 2.4210526
A16: Avg Q&A responsiveness | B16: =IFERROR(AVERAGE(N5:N10),"") -> 0.875
A17: Avg response latency (s) | B17: =IFERROR(AVERAGE(H5:H10),"") -> 11.5
A18: Avg monologue ratio | B18: =IFERROR(AVERAGE(O5:O10),"") -> 0.47777778

Sheet Interaction
A1: Interaction — questions, feedback, chat, flow
A2: Meeting-level counts from utterance classification and audio overlap detection.
A4: Inputs
A5: Questions raised | B5: 12
A6: Questions answered | B6: 10
A7: Questions deferred ("take offline") | B7: 1
A8: Questions unanswered | B8: =MAX(0,B5-B6-B7) -> 1
A9: Question resolution rate | B9: =IF(B5=0,"",B6/B5) -> 0.83333333
A10: Feedback instances | B10: 6
A11: Substantive chat messages | B11: 5
A12: Chat per attendee | B12: =IFERROR(B11/Participants!B22,"") -> 0.625 | C12: Attendee count pulled from Participants sheet
A13: Interruptions per 10 min (overlaps > 2s) | B13: 1.5
A14: Speaker turns per 10 min | B14: 8

Sheet Outcomes
A1: Outcomes — decisions, actions, minutes fidelity, follow-through
A2: Decision yield & unresolved ratio compute on the Agenda sheet.
A4: Action items
A5: Action items (total) | B5: 7
A6: Actions with owner AND due date | B6: 5
A7: Action completeness | B7: =IF(B5=0,"",B6/B5) -> 0.71428571
A9: MoM fidelity (minutes vs transcript)
A10: Transcript-derived items (decisions + actions) | B10: 9
A11: Items recorded in the minutes (MoM) | B11: 8
A12: Matched items | B12: 7
A13: Precision (matched / MoM) | B13: =IFERROR(B12/B11,"") -> 0.875
A14: Recall (matched / transcript) | B14: =IFERROR(B12/B10,"") -> 0.77777778
A15: MoM fidelity (avg of precision & recall) | B15: =IFERROR(AVERAGE(B13:B14),"") -> 0.82638889
A17: D7 Follow-through (optional — needs the prior meeting)
A18: Prior actions due by this meeting | B18: 6
A19: Prior actions closed or updated | B19: 4
A20: Prior-action closure rate | B20: =IF(B18=0,"",B19/B18) -> 0.66666667
A21: Prior unresolved topics | B21: 3
A22: …of which reappeared unresolved | B22: 1
A23: Topic recurrence | B23: =IF(B21=0,"",B22/B21) -> 0.33333333
